Workbook

Sheet data_2025
A1: times | B1: time_of_day | C1: day_ahead_price | D1: real_time_price
A2: 45658.01 | B2: =MOD(A2,1) | C2: 223.74 | D2: 330
A3: 45658.021 | B3: =MOD(A3,1) | C3: 268.98 | D3: 337
A4: 45658.031 | B4: =MOD(A4,1) | C4: 261.07 | D4: 300
A5: 45658.042 | B5: =MOD(A5,1) | C5: 254.78 | D5: 320
A6: 45658.052 | B6: =MOD(A6,1) | C6: 249.84 | D6: 320
A7: 45658.062 | B7: =MOD(A7,1) | C7: 246.43 | D7: 337
A8: 45658.073 | B8: =MOD(A8,1) | C8: 221.47 | D8: 330
A9: 45658.083 | B9: =MOD(A9,1) | C9: 167 | D9: 330
A10: 45658.094 | B10: =MOD(A10,1) | C10: 207.46 | D10: 330
A11: 45658.104 | B11: =MOD(A11,1) | C11: 159 | D11: 340
A12: 45658.115 | B12: =MOD(A12,1) | C12: 155.73 | D12: 335
A13: 45658.125 | B13: =MOD(A13,1) | C13: 173.62 | D13: 300
... A2209: 45681 | B2209: =MOD(A2209,1) | C2209: 100 | D2209: 106
A2210: 45681.01 | B2210: =MOD(A2210,1) | C2210: 143.36
A2211: 45681.021 | B2211: =MOD(A2211,1) | C2211: 178.16
A2212: 45681.031 | B2212: =MOD(A2212,1) | C2212: 186.31
A2213: 45681.042 | B2213: =MOD(A2213,1) | C2213: 162.42
A2214: 45681.052 | B2214: =MOD(A2214,1) | C2214: 127.02
A2215: 45681.062 | B2215: =MOD(A2215,1) | C2215: 60
A2216: 45681.073 | B2216: =MOD(A2216,1) | C2216: 50
A2217: 45681.083 | B2217: =MOD(A2217,1) | C2217: 39.13
A2218: 45681.094 | B2218: =MOD(A2218,1) | C2218: 22.8
A2219: 45681.104 | B2219: =MOD(A2219,1) | C2219: 22.13
A2220: 45681.115 | B2220: =MOD(A2220,1) | C2220: 0
A2221: 45681.125 | B2221: =MOD(A2221,1) | C2221: 0
... A2305: 45682 | B2305: =MOD(A2305,1) | C2305: 99
A2306: 45682.01 | B2306: =MOD(A2306,1) | C2306: 100.47 | D2306: 0
A2307: 45682.021 | B2307: =MOD(A2307,1) | C2307: 158.88 | D2307: 310.1
A2308: 45682.031 | B2308: =MOD(A2308,1) | C2308: 228.44 | D2308: 300
A2309: 45682.042 | B2309: =MOD(A2309,1) | C2309: 146.57 | D2309: 320.35
A2310: 45682.052 | B2310: =MOD(A2310,1) | C2310: 123.83 | D2310: 310.6
A2311: 45682.062 | B2311: =MOD(A2311,1) | C2311: 96.47 | D2311: 323.06
A2312: 45682.073 | B2312: =MOD(A2312,1) | C2312: 97.99 | D2312: 310.6
A2313: 45682.083 | B2313: =MOD(A2313,1) | C2313: 27.51 | D2313: 285
A2314: 45682.094 | B2314: =MOD(A2314,1) | C2314: 0.39 | D2314: 298.1
A2315: 45682.104 | B2315: =MOD(A2315,1) | C2315: 0.39 | D2315: 288
A2316: 45682.115 | B2316: =MOD(A2316,1) | C2316: 0.39 | D2316: 275
A2317: 45682.125 | B2317: =MOD(A2317,1) | C2317: 0 | D2317: 271.05
... A2977: 45689 | B2977: =MOD(A2977,1) | C2977: 271.42 | D2977: 310
...

Sheet data_2026
A1: times | B1: time_of_day | C1: day_ahead_price | D1: real_time_price
A2: 46023.01 | B2: =MOD(A2,1) | C2: 235.01 | D2: 290.1
A3: 46023.021 | B3: =MOD(A3,1) | C3: 279.76 | D3: 323.1
A4: 46023.031 | B4: =MOD(A4,1) | C4: 271.24 | D4: 247.87
A5: 46023.042 | B5: =MOD(A5,1) | C5: 266.13 | D5: 263.99
A6: 46023.052 | B6: =MOD(A6,1) | C6: 259.12 | D6: 247.01
A7: 46023.062 | B7: =MOD(A7,1) | C7: 256.98 | D7: 190.55
A8: 46023.073 | B8: =MOD(A8,1) | C8: 254.29 | D8: 222.92
A9: 46023.083 | B9: =MOD(A9,1) | C9: 255.1 | D9: 227.75
A10: 46023.094 | B10: =MOD(A10,1) | C10: 260 | D10: 240
A11: 46023.104 | B11: =MOD(A11,1) | C11: 252 | D11: 250
A12: 46023.115 | B12: =MOD(A12,1) | C12: 252.11 | D12: 150
A13: 46023.125 | B13: =MOD(A13,1) | C13: 257.25 | D13: 150.38
... A5569: 46081 | B5569: =MOD(A5569,1) | C5569: 339.2 | D5569: 295.6
A5570: 46081.01 | B5570: =MOD(A5570,1) | C5570: 321.11
A5571: 46081.021 | B5571: =MOD(A5571,1) | C5571: 373.61
A5572: 46081.031 | B5572: =MOD(A5572,1) | C5572: 362.53
A5573: 46081.042 | B5573: =MOD(A5573,1) | C5573: 347.34
A5574: 46081.052 | B5574: =MOD(A5574,1) | C5574: 338.06
A5575: 46081.062 | B5575: =MOD(A5575,1) | C5575: 331.01
A5576: 46081.073 | B5576: =MOD(A5576,1) | C5576: 326.44
A5577: 46081.083 | B5577: =MOD(A5577,1) | C5577: 324.87
A5578: 46081.094 | B5578: =MOD(A5578,1) | C5578: 318.57
A5579: 46081.104 | B5579: =MOD(A5579,1) | C5579: 321.42
A5580: 46081.115 | B5580: =MOD(A5580,1) | C5580: 307.71
A5581: 46081.125 | B5581: =MOD(A5581,1) | C5581: 301.66
... A5761: 46083 | B5761: =MOD(A5761,1) | C5761: 294.3

Sheet summary
A1: time_of_day | B1: day_ahead_2025 | C1: day_ahead_2026 | D1: real_time_2025 | E1: real_time_2026
A2: 0 | B2: =AVERAGEIF(data_2025!$B$2:$B$35041,$A2,data_2025!$C$2:$C$35041) | C2: =AVERAGEIF(data_2026!$B$2:$B$5761,$A2,data_2026!$C$2:$C$5761) | D2: =AVERAGEIF(data_2025!$B$2:$B$35041,$A2,data_2025!$D$2:$D$35041) | E2: =AVERAGEIF(data_2026!$B$2:$B$5761,$A2,data_2026!$D$2:$D$5761)
A3: 0.010416667 | B3: =AVERAGEIF(data_2025!$B$2:$B$35041,$A3,data_2025!$C$2:$C$35041) | C3: =AVERAGEIF(data_2026!$B$2:$B$5761,$A3,data_2026!$C$2:$C$5761) | D3: =AVERAGEIF(data_2025!$B$2:$B$35041,$A3,data_2025!$D$2:$D$35041) | E3: =AVERAGEIF(data_2026!$B$2:$B$5761,$A3,data_2026!$D$2:$D$5761)
A4: 0.020833333 | B4: =AVERAGEIF(data_2025!$B$2:$B$35041,$A4,data_2025!$C$2:$C$35041) | C4: =AVERAGEIF(data_2026!$B$2:$B$5761,$A4,data_2026!$C$2:$C$5761) | D4: =AVERAGEIF(data_2025!$B$2:$B$35041,$A4,data_2025!$D$2:$D$35041) | E4: =AVERAGEIF(data_2026!$B$2:$B$5761,$A4,data_2026!$D$2:$D$5761)
A5: 0.03125 | B5: =AVERAGEIF(data_2025!$B$2:$B$35041,$A5,data_2025!$C$2:$C$35041) | C5: =AVERAGEIF(data_2026!$B$2:$B$5761,$A5,data_2026!$C$2:$C$5761) | D5: =AVERAGEIF(data_2025!$B$2:$B$35041,$A5,data_2025!$D$2:$D$35041) | E5: =AVERAGEIF(data_2026!$B$2:$B$5761,$A5,data_2026!$D$2:$D$5761)
A6: 0.041666667 | B6: =AVERAGEIF(data_2025!$B$2:$B$35041,$A6,data_2025!$C$2:$C$35041) | C6: =AVERAGEIF(data_2026!$B$2:$B$5761,$A6,data_2026!$C$2:$C$5761) | D6: =AVERAGEIF(data_2025!$B$2:$B$35041,$A6,data_2025!$D$2:$D$35041) | E6: =AVERAGEIF(data_2026!$B$2:$B$5761,$A6,data_2026!$D$2:$D$5761)
A7: 0.052083333 | B7: =AVERAGEIF(data_2025!$B$2:$B$35041,$A7,data_2025!$C$2:$C$35041) | C7: =AVERAGEIF(data_2026!$B$2:$B$5761,$A7,data_2026!$C$2:$C$5761) | D7: =AVERAGEIF(data_2025!$B$2:$B$35041,$A7,data_2025!$D$2:$D$35041) | E7: =AVERAGEIF(data_2026!$B$2:$B$5761,$A7,data_2026!$D$2:$D$5761)
A8: 0.0625 | B8: =AVERAGEIF(data_2025!$B$2:$B$35041,$A8,data_2025!$C$2:$C$35041) | C8: =AVERAGEIF(data_2026!$B$2:$B$5761,$A8,data_2026!$C$2:$C$5761) | D8: =AVERAGEIF(data_2025!$B$2:$B$35041,$A8,data_2025!$D$2:$D$35041) | E8: =AVERAGEIF(data_2026!$B$2:$B$5761,$A8,data_2026!$D$2:$D$5761)
A9: 0.072916667 | B9: =AVERAGEIF(data_2025!$B$2:$B$35041,$A9,data_2025!$C$2:$C$35041) | C9: =AVERAGEIF(data_2026!$B$2:$B$5761,$A9,data_2026!$C$2:$C$5761) | D9: =AVERAGEIF(data_2025!$B$2:$B$35041,$A9,data_2025!$D$2:$D$35041) | E9: =AVERAGEIF(data_2026!$B$2:$B$5761,$A9,data_2026!$D$2:$D$5761)
A10: 0.083333333 | B10: =AVERAGEIF(data_2025!$B$2:$B$35041,$A10,data_2025!$C$2:$C$35041) | C10: =AVERAGEIF(data_2026!$B$2:$B$5761,$A10,data_2026!$C$2:$C$5761) | D10: =AVERAGEIF(data_2025!$B$2:$B$35041,$A10,data_2025!$D$2:$D$35041) | E10: =AVERAGEIF(data_2026!$B$2:$B$5761,$A10,data_2026!$D$2:$D$5761)
A11: 0.09375 | B11: =AVERAGEIF(data_2025!$B$2:$B$35041,$A11,data_2025!$C$2:$C$35041) | C11: =AVERAGEIF(data_2026!$B$2:$B$5761,$A11,data_2026!$C$2:$C$5761) | D11: =AVERAGEIF(data_2025!$B$2:$B$35041,$A11,data_2025!$D$2:$D$35041) | E11: =AVERAGEIF(data_2026!$B$2:$B$5761,$A11,data_2026!$D$2:$D$5761)
A12: 0.10416667 | B12: =AVERAGEIF(data_2025!$B$2:$B$35041,$A12,data_2025!$C$2:$C$35041) | C12: =AVERAGEIF(data_2026!$B$2:$B$5761,$A12,data_2026!$C$2:$C$5761) | D12: =AVERAGEIF(data_2025!$B$2:$B$35041,$A12,data_2025!$D$2:$D$35041) | E12: =AVERAGEIF(data_2026!$B$2:$B$5761,$A12,data_2026!$D$2:$D$5761)
A13: 0.11458333 | B13: =AVERAGEIF(data_2025!$B$2:$B$35041,$A13,data_2025!$C$2:$C$35041) | C13: =AVERAGEIF(data_2026!$B$2:$B$5761,$A13,data_2026!$C$2:$C$5761) | D13: =AVERAGEIF(data_2025!$B$2:$B$35041,$A13,data_2025!$D$2:$D$35041) | E13: =AVERAGEIF(data_2026!$B$2:$B$5761,$A13,data_2026!$D$2:$D$5761)
... A97: 0.98958333 | B97: =AVERAGEIF(data_2025!$B$2:$B$35041,$A97,data_2025!$C$2:$C$35041) | C97: =AVERAGEIF(data_2026!$B$2:$B$5761,$A97,data_2026!$C$2:$C$5761) | D97: =AVERAGEIF(data_2025!$B$2:$B$35041,$A97,data_2025!$D$2:$D$35041) | E97: =AVERAGEIF(data_2026!$B$2:$B$5761,$A97,data_2026!$D$2:$D$5761)
